Workbook
Name PD_TERM_GRADE: Inputs!$A$7:$A$216
Name PD_TERM_YEAR: Inputs!$B$7:$B$216
Name PD_TERM_CUM: Inputs!$D$7:$D$216
Name LGD_SEGMENT: Inputs!$B$220:$B$225
Name LGD_VALUE: Inputs!$C$220:$C$225
Name LGD_OVERALL: Inputs!$C$220
Name DISCOUNT_RATE: Inputs!$B$228
Name SICR_RATIO: Inputs!$B$233
Name SICR_ABSOLUTE: Inputs!$D$233
Name SCENARIO_WEIGHT: Inputs!$B$239:$B$241
Name FICO_LOWER: Scorecard!$C$6:$C$13
Name FICO_POINTS: Scorecard!$E$6:$E$13
Name LTV_PCT_LOWER: Scorecard!$C$14:$C$21
Name LTV_PCT_POINTS: Scorecard!$E$14:$E$21
Name DTI_PCT_LOWER: Scorecard!$C$22:$C$29
Name DTI_PCT_POINTS: Scorecard!$E$22:$E$29
Name RATE_SPREAD_PCT_LOWER: Scorecard!$C$30:$C$37
Name RATE_SPREAD_PCT_POINTS: Scorecard!$E$30:$E$37
Name CHANNEL_KEY: Scorecard!$D$38:$D$41
Name CHANNEL_POINTS: Scorecard!$E$38:$E$41
Name PROPERTY_TYPE_KEY: Scorecard!$D$42:$D$45
Name PROPERTY_TYPE_POINTS: Scorecard!$E$42:$E$45
Name TERM_BAND_KEY: Scorecard!$D$46:$D$48
Name TERM_BAND_POINTS: Scorecard!$E$46:$E$48
Name GRADE_SCORE_MIN: Scorecard!$B$52:$B$58
Name GRADE_LETTER: Scorecard!$A$52:$A$58
Name EXAMPLE_SCORE: Scorecard!$C$68
Name ECL_GRADE: ECL!$A$5:$A$25
Name ECL_STAGE: ECL!$B$5:$B$25
Name ECL_EAD: ECL!$D$5:$D$25
Name ECL_VALUE: ECL!$E$5:$E$25
Name TOTAL_EAD: ECL!$C$28
Name ECL_12M: ECL!$C$29
Name ECL_LIFETIME: ECL!$C$30
Name TOTAL_ECL: ECL!$C$31

Sheet Inputs
A1: Vintage ECL workbook -- Inputs
A2: US mortgages (Freddie Mac Single-Family Loan-Level sample, non-commercial research). Illustrative: demonstrates a portfolio-lifecycle IFRS 9 workflow, not a production model or regulatory submission.
A3: Every number below is pulled from the project's published artefacts (pd_models.json, lgd_ead.json, ecl.json). Yellow cells are pulled inputs; blue cells are live formulas.
A5: PD term structure by grade
A6: grade | B6: year | C6: marginal_pd | D6: cumulative_pd
A7: A | B7: 1 | C7: 0.0012967019 | D7: 0.0012967019
A8: A | B8: 2 | C8: 0.0014754241 | D8: 0.002772126
A9: A | B9: 3 | C9: 0.0016556992 | D9: 0.0044278252
A10: A | B10: 4 | C10: 0.0012403857 | D10: 0.0056682109
A11: A | B11: 5 | C11: 0.0011400081 | D11: 0.006808219
A12: A | B12: 6 | C12: 0.00064410828 | D12: 0.0074523272
A13: A | B13: 7 | C13: 0.00053830748 | D13: 0.0079906347
A14: A | B14: 8 | C14: 0.00047306442 | D14: 0.0084636991
A15: A | B15: 9 | C15: 0.00041572884 | D15: 0.008879428
A16: A | B16: 10 | C16: 0.00036534235 | D16: 0.0092447703
A17: A | B17: 11 | C17: 0.00024304191 | D17: 0.0094878122
A18: A | B18: 12 | C18: 0.00022213846 | D18: 0.0097099507
... A216: G | B216: 30 | C216: 0.0020691609 | D216: 0.28479407
A218: LGD by segment (economic, net of MI)
A219: dimension | B219: segment | C219: lgd_economic | D219: n
A220: overall | B220: all | C220: 0.24910646 | D220: 35688
A221: ltv_band | B221: 60_80 | C221: 0.28896718 | D221: 20017
A222: ltv_band | B222: 80_90 | C222: 0.25542934 | D222: 5081
A223: ltv_band | B223: 90_95 | C223: 0.17396191 | D223: 3813
A224: ltv_band | B224: gt_95 | C224: 0.23589383 | D224: 2408
A225: ltv_band | B225: le_60 | C225: 0.13199121 | D225: 4369
A227: Discount rate
A228: Portfolio weighted-average note rate (real, aggregate) | B228: 0.051499672 | C228: n = 1,349,995 loans, weighted by original UPB
A229: The published ECL discounts each loan at its own note rate (CONTRACTS.md: discount_factor = (1+note_rate_pct/1200)^-months_to_resolution). The portfolio average above is used only in this workbook's illustrative sensitivity table, not in the reconciled ECL totals on the ECL sheet.
A231: IFRS 9 stage rules
A232: Stage 1: performing
A233: Stage 2: 30+ days past due, or PD deterioration ratio >= | B233: 2 | C233: or absolute PD increase >= | D233: 0.002
A234: Stage 3: defaulted
A236: Scenario weights
A237: Source: FHFA HPI, national (USA), purchase-only, monthly, seasonally adjusted (hpi_master.csv)
A238: scenario | B238: weight
A239: base | B239: 0.6
A240: adverse | B240: 0.25
A241: upside | B241: 0.15

Sheet Scorecard
A1: Scorecard -- points table and one worked example
A2: 12-month PD, 1999-2015 development average. Base score 600, base odds 50.0:1, PDO 20. Lookup uses INDEX/MATCH (not XLOOKUP), for compatibility with older Excel.
A4: Points table
A5: feature | B5: bin | C5: lower | D5: match_key | E5: points
A6: fico | B6: [-inf, 654.5) | C6: -1e+15 | E6: 57
A7: fico | B7: [654.5, 680.5) | C7: 654.5 | E7: 75
A8: fico | B8: [680.5, 699.5) | C8: 680.5 | E8: 85
A9: fico | B9: [699.5, 715.5) | C9: 699.5 | E9: 94
A10: fico | B10: [715.5, 728.5) | C10: 715.5 | E10: 101
A11: fico | B11: [728.5, 754.5) | C11: 728.5 | E11: 109
A12: fico | B12: [754.5, 783.5) | C12: 754.5 | E12: 121
A13: fico | B13: [783.5, inf) | C13: 783.5 | E13: 135
A14: ltv_pct | B14: [-inf, 36.5) | C14: -1e+15 | E14: 112
A15: ltv_pct | B15: [36.5, 54.5) | C15: 36.5 | E15: 108
A16: ltv_pct | B16: [54.5, 59.5) | C16: 54.5 | E16: 102
A17: ltv_pct | B17: [59.5, 69.5) | C17: 59.5 | E17: 98
... A37: rate_spread_pct | B37: [0.6245, inf) | C37: 0.6245 | E37: 61
A38: channel | B38: [C] | D38: C | E38: 101
A39: channel | B39: [R] | D39: R | E39: 100
A40: channel | B40: [T] | D40: T | E40: 84
A41: channel | B41: [B] | D41: B | E41: 87
A42: property_type | B42: [PU] | D42: PU | E42: 99
A43: property_type | B43: [CO] | D43: CO | E43: 92
A44: property_type | B44: [SF] | D44: SF | E44: 92
A45: property_type | B45: [MH, CP] | D45: MH | E45: 90
A46: term_band | B46: [le_180] | D46: le_180 | E46: 110
A47: term_band | B47: [181_240] | D47: 181_240 | E47: 102
A48: term_band | B48: [gt_240] | D48: gt_240 | E48: 89
A50: Grades (ascending score)
A51: grade | B51: score_min | C51: pd_low | D51: pd_high
A52: F | B52: 586 | C52: 0.016 | D52: 0.032
A53: E | B53: 606 | C53: 0.008 | D53: 0.016
A54: D | B54: 627 | C54: 0.004 | D54: 0.008
A55: C | B55: 647 | C55: 0.002 | D55: 0.004
A56: B | B56: 667 | C56: 0.001 | D56: 0.002
A57: A | B57: 687 | C57: 0 | D57: 0.001
A58: G | B58: -1e+15 | C58: 0.032 | D58: 1
A60: Example loan
A61: fico | B61: 705 | C61: =INDEX(Scorecard!$E$6:$E$13,MATCH(B61,Scorecard!$C$6:$C$13,1))
A62: ltv_pct | B62: 82 | C62: =INDEX(Scorecard!$E$14:$E$21,MATCH(B62,Scorecard!$C$14:$C$21,1))
...

Sheet ECL
A1: ECL by grade x stage -- reporting date 2026-03-01
A2: Aggregates only (every row is >= 10 loans). ECL and coverage are the published portfolio-level figures, loaded here and aggregated with live formulas (SUMIF). Confidence intervals reflect parameter uncertainty only (from repeated parameter draws), not model or sampling uncertainty.
A4: grade | B4: stage | C4: n_loans | D4: ead | E4: ecl | F4: ecl_ci_low | G4: ecl_ci_high | H4: coverage
A5: A | B5: 1 | C5: 152375 | D5: 3.4242969e+10 | E5: 6762066.7 | F5: 6633146.4 | G5: 6892784.2 | H5: =E5/D5
A6: A | B6: 2 | C6: 2876 | D6: 5.9633234e+08 | E6: 2368938.5 | F6: 2326620.9 | G6: 2411958.6 | H6: =E6/D6
A7: A | B7: 3 | C7: 318 | D7: 60222648 | E7: 8416843.3 | F7: 8416843.3 | G7: 8416843.3 | H7: =E7/D7
A8: B | B8: 1 | C8: 55145 | D8: 1.3638758e+10 | E8: 8255886.6 | F8: 8123142.4 | G8: 8403323 | H8: =E8/D8
A9: B | B9: 2 | C9: 16164 | D9: 4.3279518e+09 | E9: 19506936 | F9: 18870320 | G9: 20137621 | H9: =E9/D9
A10: B | B10: 3 | C10: 451 | D10: 1.1775728e+08 | E10: 14812178 | F10: 14812178 | G10: 14812178 | H10: =E10/D10
A11: C | B11: 1 | C11: 40218 | D11: 9.5980497e+09 | E11: 9246966.6 | F11: 9111018.7 | G11: 9383524.5 | H11: =E11/D11
A12: C | B12: 2 | C12: 12655 | D12: 3.2412425e+09 | E12: 28862471 | F12: 28060884 | G12: 29621473 | H12: =E12/D12
A13: C | B13: 3 | C13: 658 | D13: 1.6596749e+08 | E13: 22942046 | F13: 22942046 | G13: 22942046 | H13: =E13/D13
A14: D | B14: 1 | C14: 24285 | D14: 5.5708986e+09 | E14: 7637065 | F14: 7522427.8 | G14: 7748560.3 | H14: =E14/D14
A15: D | B15: 2 | C15: 7801 | D15: 1.9058285e+09 | E15: 28217744 | F15: 27567139 | G15: 28843789 | H15: =E15/D15
A16: D | B16: 3 | C16: 635 | D16: 153555041 | E16: 23265346 | F16: 23265346 | G16: 23265346 | H16: =E16/D16
... A25: G | B25: 3 | C25: 127 | D25: 31136047 | E25: 5265457.2 | F25: 5265457.2 | G25: 5265457.2 | H25: =E25/D25
A27: Portfolio totals
A28: Total EAD | C28: =SUM(ECL_EAD)
A29: 12-month ECL (stage 1) | C29: =SUMIF(ECL_STAGE,"1",ECL_VALUE)
A30: Lifetime ECL (stage 2 + 3) | C30: =SUMIF(ECL_STAGE,"2",ECL_VALUE)+SUMIF(ECL_STAGE,"3",ECL_VALUE)
A31: Total ECL | C31: =C29+C30
A32: Portfolio coverage ratio | C32: =C31/C28
A34: Sensitivity: total ECL under LGD/PD multipliers
A35: Illustrative overlay only (Total ECL x PD multiplier x LGD multiplier). Not a re-run of the hazard/LGD model, and not part of the reconciled totals above.
A36: PD mult \ LGD mult | B36: 0.8 | C36: 1 | D36: 1.2
A37: 0.8 | B37: =TOTAL_ECL*0.8*B$36 | C37: =TOTAL_ECL*0.8*C$36 | D37: =TOTAL_ECL*0.8*D$36
A38: 1 | B38: =TOTAL_ECL*1.0*B$36 | C38: =TOTAL_ECL*1.0*C$36 | D38: =TOTAL_ECL*1.0*D$36
A39: 1.2 | B39: =TOTAL_ECL*1.2*B$36 | C39: =TOTAL_ECL*1.2*C$36 | D39: =TOTAL_ECL*1.2*D$36

Sheet Summary
A1: Summary
A2: US mortgages (Freddie Mac sample, non-commercial research). Illustrative workbook; the ECL intervals shown reflect parameter uncertainty only, not model or sampling risk.
A4: Total EAD | B4: =TOTAL_EAD
A5: 12-month ECL (stage 1) | B5: =ECL_12M
A6: Lifetime ECL (stage 2 + 3) | B6: =ECL_LIFETIME
A7: Total ECL | B7: =TOTAL_ECL
A8: Coverage ratio | B8: =TOTAL_ECL/TOTAL_EAD
A10: Stage mix (EAD)
A11: stage | B11: ead
A12: Stage 1 | B12: =SUMIF(ECL_STAGE,"1",ECL_EAD)
A13: Stage 2 | B13: =SUMIF(ECL_STAGE,"2",ECL_EAD)
A14: Stage 3 | B14: =SUMIF(ECL_STAGE,"3",ECL_EAD)
